<?xml version="1.0" ?>
<!-- =================================================================================== -->
<!-- |    This document was autogenerated by xacro from rrbot.xacro                    | -->
<!-- |    EDITING THIS FILE BY HAND IS NOT RECOMMENDED                                 | -->
<!-- =================================================================================== -->
<!-- Revolute-Revolute Manipulator -->
<robot name="rrbot" xmlns:xacro="http://www.ros.org/wiki/xacro">
  <!-- Constants for robot dimensions -->
  <!-- Square dimensions (width x width) of beams  0.1-->
  <!--was 0.397-->
  <!--was 0.1789-->
  <!-- old 0.102 is double radius without ground_clearance 0.07683 -->
  <!--was 0.09-->
  <!--was 0.09-->
  <!--old 0.05 0.02517-->
  <!-- ros_control plugin -->
  <gazebo>
    <plugin filename="libgazebo_ros_control.so" name="gazebo_ros_control">
      <robotNamespace>/rrbot</robotNamespace>
      <robotSimType>gazebo_ros_control/DefaultRobotHWSim</robotSimType>
    </plugin>
  </gazebo>
  <gazebo reference="base_link">
    <material>Gazebo/Orange</material>
  </gazebo>
  <gazebo reference="left_flipper">
    <mu1>0.01</mu1>
    <mu2>0.01</mu2>
    <material>Gazebo/Grey</material>
  </gazebo>
  <gazebo reference="right_flipper">
    <mu1>0.01</mu1>
    <mu2>0.01</mu2>
    <material>Gazebo/Grey</material>
  </gazebo>
  <gazebo reference="right_front_base_link">
    <mu1>10000</mu1>
    <mu2>10000</mu2>
    <material>Gazebo/Grey</material>
  </gazebo>
  <gazebo reference="left_front_base_link_wheel">
    <mu1>10000</mu1>
    <mu2>10000</mu2>
    <material>Gazebo/Grey</material>
  </gazebo>
  <gazebo reference="right_rear_base_link_wheel">
    <mu1>10000</mu1>
    <mu2>10000</mu2>
    <material>Gazebo/Grey</material>
  </gazebo>
  <gazebo reference="left_rear_base_link_wheel">
    <mu1>10000</mu1>
    <mu2>10000</mu2>
    <material>Gazebo/Grey</material>
  </gazebo>
  <gazebo reference="right_flipper_wheel">
    <mu1>10000</mu1>
    <mu2>10000</mu2>
    <material>Gazebo/Grey</material>
  </gazebo>
  <gazebo reference="left_flipper_wheel">
    <mu1>10000</mu1>
    <mu2>10000</mu2>
    <material>Gazebo/Grey</material>
  </gazebo>
  <material name="black">
    <color rgba="0.0 0.0 0.0 1.0"/>
  </material>
  <material name="blue">
    <color rgba="0.0 0.0 0.8 1.0"/>
  </material>
  <material name="green">
    <color rgba="0.0 0.8 0.0 1.0"/>
  </material>
  <material name="grey">
    <color rgba="0.2 0.2 0.2 1.0"/>
  </material>
  <material name="orange">
    <color rgba="1.0 0.423529411765 0.0392156862745 1.0"/>
  </material>
  <material name="brown">
    <color rgba="0.870588235294 0.811764705882 0.764705882353 1.0"/>
  </material>
  <material name="red">
    <color rgba="0.8 0.0 0.0 1.0"/>
  </material>
  <material name="white">
    <color rgba="1.0 1.0 1.0 1.0"/>
  </material>
  <link name="base_link">
    <visual>
      <origin rpy="0 0 0" xyz="0 0 0"/>
      <geometry>
        <mesh filename="package://rrbot_description/meshes/Base.dae" scale="1 1 1"/>
      </geometry>
      <material name="orange"/>
      --&gt;
        
    </visual>
    <collision>
      <origin rpy="0 0 0" xyz="0 0 0"/>
      <geometry>
        <mesh filename="package://rrbot_description/meshes/Base.dae" scale="1 1 1"/>
      </geometry>
    </collision>
    <inertial>
      <origin rpy="0 0 0" xyz="0 0 0"/>
      <mass value="10"/>
      <inertia ixx="1" ixy="0.0" ixz="0.0" iyy="1" iyz="0.0" izz="1"/>
    </inertial>
  </link>
  <link name="right_flipper">
    <visual>
      <origin rpy="0 0 0" xyz="0 0 0"/>
      <geometry>
        <mesh filename="package://rrbot_description/meshes/Flipper.dae" scale="1 1 1"/>
      </geometry>
      <material name="black"/>
      --&gt;
        
    </visual>
    <collision>
      <origin rpy="0 0 0" xyz="0 0 0"/>
      <geometry>
        <mesh filename="package://rrbot_description/meshes/Flipper.dae" scale="1 1 1"/>
      </geometry>
    </collision>
    <inertial>
      <origin rpy="0 0 0" xyz="0 0 0"/>
      <mass value="0.775"/>
      <inertia ixx="1" ixy="0.0" ixz="0.0" iyy="1" iyz="0.0" izz="1"/>
    </inertial>
  </link>
  <joint name="joint_right_flipper" type="revolute">
    <parent link="base_link"/>
    <child link="right_flipper"/>
    <origin rpy="0 0 0" xyz="2.2 1.86 -0.25"/>
    <axis xyz="1 0 0"/>
    <limit effort="100" lower="-6.283" upper="6.283" velocity="100"/>
  </joint>
  <transmission name="tran_joint_right_flipper">
    <type>transmission_interface/SimpleTransmission</type>
    <joint name="joint_right_flipper">
      <hardwareInterface>EffortJointInterface</hardwareInterface>
    </joint>
    <actuator name="motor_joint_right_flipper">
      <hardwareInterface>EffortJointInterface</hardwareInterface>
      <mechanicalReduction>1</mechanicalReduction>
    </actuator>
  </transmission>
  <link name="left_flipper">
    <visual>
      <origin rpy="0 0 0" xyz="0 0 0"/>
      <geometry>
        <mesh filename="package://rrbot_description/meshes/Flipper.dae" scale="1 1 1"/>
      </geometry>
      <material name="black"/>
      --&gt;
        
    </visual>
    <collision>
      <origin rpy="0 0 0" xyz="0 0 0"/>
      <geometry>
        <mesh filename="package://rrbot_description/meshes/Flipper.dae" scale="1 1 1"/>
      </geometry>
    </collision>
    <inertial>
      <origin rpy="0 0 0" xyz="0 0 0"/>
      <mass value="0.775"/>
      <inertia ixx="1" ixy="0.0" ixz="0.0" iyy="1" iyz="0.0" izz="1"/>
    </inertial>
  </link>
  <joint name="joint_left_flipper" type="revolute">
    <parent link="base_link"/>
    <child link="left_flipper"/>
    <origin rpy="0 3.1415 0" xyz="-2.2 1.86 -0.25"/>
    <axis xyz="1 0 0"/>
    <limit effort="100" lower="-6.283" upper="6.283" velocity="100"/>
  </joint>
  <transmission name="tran_joint_left_flipper">
    <type>transmission_interface/SimpleTransmission</type>
    <joint name="joint_left_flipper">
      <hardwareInterface>EffortJointInterface</hardwareInterface>
    </joint>
    <actuator name="motor_joint_left_flipper">
      <hardwareInterface>EffortJointInterface</hardwareInterface>
      <mechanicalReduction>1</mechanicalReduction>
    </actuator>
  </transmission>
  <link name="right_front_base_link_wheel">
    <visual>
      <origin rpy="0 0 0" xyz="0 0 0"/>
      <geometry>
        <cylinder length="0.2" radius="0.8"/>
      </geometry>
    </visual>
    <collision>
      <origin rpy="0 0 0" xyz="0 0 0"/>
      <geometry>
        <cylinder length="0.2" radius="0.8"/>
      </geometry>
    </collision>
    <inertial>
      <origin rpy="0 0 0" xyz="0 0 0"/>
      <mass value="0.0001"/>
      <inertia ixx="1" ixy="0.0" ixz="0.0" iyy="1" iyz="0.0" izz="1"/>
    </inertial>
  </link>
  <joint name="joint_right_front_base_link_wheel" type="continuous">
    <parent link="base_link"/>
    <child link="right_front_base_link_wheel"/>
    <origin rpy="0 1.57075 3.1415" xyz="4 1.86 -0.25"/>
    <axis xyz="0 0 1"/>
    <limit effort="100" velocity="20"/>
  </joint>
  <transmission name="tran_joint_right_front_base_link_wheel">
    <type>transmission_interface/SimpleTransmission</type>
    <joint name="joint_right_front_base_link_wheel">
      <hardwareInterface>VelocityJointInterface</hardwareInterface>
    </joint>
    <actuator name="motor_joint_right_front_base_link_wheel">
      <hardwareInterface>VelocityJointInterface</hardwareInterface>
      <mechanicalReduction>1</mechanicalReduction>
    </actuator>
  </transmission>
  <link name="left_front_base_link_wheel">
    <visual>
      <origin rpy="0 0 0" xyz="0 0 0"/>
      <geometry>
        <cylinder length="0.2" radius="0.8"/>
      </geometry>
    </visual>
    <collision>
      <origin rpy="0 0 0" xyz="0 0 0"/>
      <geometry>
        <cylinder length="0.2" radius="0.8"/>
      </geometry>
    </collision>
    <inertial>
      <origin rpy="0 0 0" xyz="0 0 0"/>
      <mass value="0.0001"/>
      <inertia ixx="1" ixy="0.0" ixz="0.0" iyy="1" iyz="0.0" izz="1"/>
    </inertial>
  </link>
  <joint name="joint_left_front_base_link_wheel" type="continuous">
    <parent link="base_link"/>
    <child link="left_front_base_link_wheel"/>
    <origin rpy="0 1.57075 3.1415" xyz="-4 1.86 -0.25"/>
    <axis xyz="0 0 1"/>
    <limit effort="100" velocity="20"/>
  </joint>
  <transmission name="tran_joint_left_front_base_link_wheel">
    <type>transmission_interface/SimpleTransmission</type>
    <joint name="joint_left_front_base_link_wheel">
      <hardwareInterface>VelocityJointInterface</hardwareInterface>
    </joint>
    <actuator name="motor_joint_left_front_base_link_wheel">
      <hardwareInterface>VelocityJointInterface</hardwareInterface>
      <mechanicalReduction>1</mechanicalReduction>
    </actuator>
  </transmission>
  <link name="right_rear_base_link_wheel">
    <visual>
      <origin rpy="0 0 0" xyz="0 0 0"/>
      <geometry>
        <cylinder length="0.2" radius="0.8"/>
      </geometry>
    </visual>
    <collision>
      <origin rpy="0 0 0" xyz="0 0 0"/>
      <geometry>
        <cylinder length="0.2" radius="0.8"/>
      </geometry>
    </collision>
    <inertial>
      <origin rpy="0 0 0" xyz="0 0 0"/>
      <mass value="0.0001"/>
      <inertia ixx="1" ixy="0.0" ixz="0.0" iyy="1" iyz="0.0" izz="1"/>
    </inertial>
  </link>
  <joint name="joint_right_rear_base_link_wheel" type="continuous">
    <parent link="base_link"/>
    <child link="right_rear_base_link_wheel"/>
    <origin rpy="0 1.57075 3.1415" xyz="4 -1.86 -0.25"/>
    <axis xyz="0 0 1"/>
    <limit effort="100" velocity="20"/>
  </joint>
  <transmission name="tran_joint_right_rear_base_link_wheel">
    <type>transmission_interface/SimpleTransmission</type>
    <joint name="joint_right_rear_base_link_wheel">
      <hardwareInterface>VelocityJointInterface</hardwareInterface>
    </joint>
    <actuator name="motor_joint_right_rear_base_link_wheel">
      <hardwareInterface>VelocityJointInterface</hardwareInterface>
      <mechanicalReduction>1</mechanicalReduction>
    </actuator>
  </transmission>
  <link name="left_rear_base_link_wheel">
    <visual>
      <origin rpy="0 0 0" xyz="0 0 0"/>
      <geometry>
        <cylinder length="0.2" radius="0.8"/>
      </geometry>
    </visual>
    <collision>
      <origin rpy="0 0 0" xyz="0 0 0"/>
      <geometry>
        <cylinder length="0.2" radius="0.8"/>
      </geometry>
    </collision>
    <inertial>
      <origin rpy="0 0 0" xyz="0 0 0"/>
      <mass value="0.0001"/>
      <inertia ixx="1" ixy="0.0" ixz="0.0" iyy="1" iyz="0.0" izz="1"/>
    </inertial>
  </link>
  <joint name="joint_left_rear_base_link_wheel" type="continuous">
    <parent link="base_link"/>
    <child link="left_rear_base_link_wheel"/>
    <origin rpy="0 1.57075 3.1415" xyz="-4 -1.86 -0.25"/>
    <axis xyz="0 0 1"/>
    <limit effort="100" velocity="20"/>
  </joint>
  <transmission name="tran_joint_left_rear_base_link_wheel">
    <type>transmission_interface/SimpleTransmission</type>
    <joint name="joint_left_rear_base_link_wheel">
      <hardwareInterface>VelocityJointInterface</hardwareInterface>
    </joint>
    <actuator name="motor_joint_left_rear_base_link_wheel">
      <hardwareInterface>VelocityJointInterface</hardwareInterface>
      <mechanicalReduction>1</mechanicalReduction>
    </actuator>
  </transmission>
  <link name="right_flipper_wheel">
    <visual>
      <origin rpy="0 0 0" xyz="0 0 0"/>
      <geometry>
        <cylinder length="0.2" radius="0.5"/>
      </geometry>
    </visual>
    <collision>
      <origin rpy="0 0 0" xyz="0 0 0"/>
      <geometry>
        <cylinder length="0.2" radius="0.5"/>
      </geometry>
    </collision>
    <inertial>
      <origin rpy="0 0 0" xyz="0 0 0"/>
      <mass value="0.0001"/>
      <inertia ixx="1" ixy="0.0" ixz="0.0" iyy="1" iyz="0.0" izz="1"/>
    </inertial>
  </link>
  <joint name="joint_right_flipper_wheel" type="continuous">
    <parent link="right_flipper"/>
    <child link="right_flipper_wheel"/>
    <origin rpy="0 1.57075 3.1415" xyz="0.3 3.4 0"/>
    <axis xyz="0 0 1"/>
    <limit effort="100" velocity="20"/>
  </joint>
  <transmission name="tran_joint_right_flipper_wheel">
    <type>transmission_interface/SimpleTransmission</type>
    <joint name="joint_right_flipper_wheel">
      <hardwareInterface>VelocityJointInterface</hardwareInterface>
    </joint>
    <actuator name="motor_joint_right_flipper_wheel">
      <hardwareInterface>VelocityJointInterface</hardwareInterface>
      <mechanicalReduction>1</mechanicalReduction>
    </actuator>
  </transmission>
  <link name="left_flipper_wheel">
    <visual>
      <origin rpy="0 0 0" xyz="0 0 0"/>
      <geometry>
        <cylinder length="0.2" radius="0.5"/>
      </geometry>
    </visual>
    <collision>
      <origin rpy="0 0 0" xyz="0 0 0"/>
      <geometry>
        <cylinder length="0.2" radius="0.5"/>
      </geometry>
    </collision>
    <inertial>
      <origin rpy="0 0 0" xyz="0 0 0"/>
      <mass value="0.0001"/>
      <inertia ixx="1" ixy="0.0" ixz="0.0" iyy="1" iyz="0.0" izz="1"/>
    </inertial>
  </link>
  <joint name="joint_left_flipper_wheel" type="continuous">
    <parent link="left_flipper"/>
    <child link="left_flipper_wheel"/>
    <origin rpy="0 1.57075 3.1415" xyz="5 3.4 0"/>
    <axis xyz="0 0 1"/>
    <limit effort="100" velocity="20"/>
  </joint>
  <transmission name="tran_joint_left_flipper_wheel">
    <type>transmission_interface/SimpleTransmission</type>
    <joint name="joint_left_flipper_wheel">
      <hardwareInterface>VelocityJointInterface</hardwareInterface>
    </joint>
    <actuator name="motor_joint_left_flipper_wheel">
      <hardwareInterface>VelocityJointInterface</hardwareInterface>
      <mechanicalReduction>1</mechanicalReduction>
    </actuator>
  </transmission>
  <link name="cronstein">
    <visual>
      <origin rpy="0 0 0" xyz="0 0 0"/>
      <geometry>
        <mesh filename="package://rrbot_description/meshes/cronstain2.dae" scale="1 1 1"/>
      </geometry>
      <material name="red"/>
      --&gt;
        
    </visual>
    <collision>
      <origin rpy="0 0 0" xyz="0 0 0"/>
      <geometry>
        <mesh filename="package://rrbot_description/meshes/cronstain2.dae" scale="1 1 1"/>
      </geometry>
    </collision>
    <inertial>
      <origin rpy="0 0 0" xyz="0 0 0"/>
      <mass value="0.477"/>
      <inertia ixx="1" ixy="0.0" ixz="0.0" iyy="1" iyz="0.0" izz="1"/>
    </inertial>
  </link>
  <joint name="joint_cronstein" type="revolute">
    <parent link="base_link"/>
    <child link="cronstein"/>
    <origin rpy="0 1.57075 1.57075" xyz="0 -1.75 0.6"/>
    <axis xyz="1 0 0"/>
    <limit effort="100" lower="-6.283" upper="6.283" velocity="100"/>
  </joint>
  <transmission name="tran_joint_cronstein">
    <type>transmission_interface/SimpleTransmission</type>
    <joint name="joint_cronstein">
      <hardwareInterface>EffortJointInterface</hardwareInterface>
    </joint>
    <actuator name="motor_joint_cronstein">
      <hardwareInterface>EffortJointInterface</hardwareInterface>
      <mechanicalReduction>1</mechanicalReduction>
    </actuator>
  </transmission>
  <!--x="0.5" y="-1.05" z="1.1" roll="0" pitch="${PI*0.5}" yaw="${PI*0.5}" axis="0 0 1"/>-->
  <link name="first_part">
    <visual>
      <origin rpy="0 0 0" xyz="0 0 0"/>
      <geometry>
        <mesh filename="package://rrbot_description/meshes/first_part_of_arm.dae" scale="0.01 0.01 0.01"/>
      </geometry>
      <material name="red"/>
      --&gt;
        
    </visual>
    <collision>
      <origin rpy="0 0 0" xyz="0 0 0"/>
      <geometry>
        <mesh filename="package://rrbot_description/meshes/first_part_of_arm.dae" scale="0.01 0.01 0.01"/>
      </geometry>
    </collision>
    <inertial>
      <origin rpy="0 0 0" xyz="0 0 0"/>
      <mass value="2.231"/>
      <inertia ixx="1" ixy="0.0" ixz="0.0" iyy="1" iyz="0.0" izz="1"/>
    </inertial>
  </link>
  <joint name="joint_first_part" type="revolute">
    <parent link="cronstein"/>
    <child link="first_part"/>
    <origin rpy="3.1415 3.1415 1.57075" xyz="-0.54 0.25 0.7"/>
    <axis xyz="1 0 0"/>
    <limit effort="100" lower="-6.283" upper="6.283" velocity="100"/>
  </joint>
  <transmission name="tran_joint_first_part">
    <type>transmission_interface/SimpleTransmission</type>
    <joint name="joint_first_part">
      <hardwareInterface>EffortJointInterface</hardwareInterface>
    </joint>
    <actuator name="motor_joint_first_part">
      <hardwareInterface>EffortJointInterface</hardwareInterface>
      <mechanicalReduction>1</mechanicalReduction>
    </actuator>
  </transmission>
  <link name="second_part">
    <visual>
      <origin rpy="0 0 0" xyz="0 0 0"/>
      <geometry>
        <mesh filename="package://rrbot_description/meshes/second_part_of_arm.dae" scale="0.01 0.01 0.01"/>
      </geometry>
      <material name="red"/>
      --&gt;
        
    </visual>
    <collision>
      <origin rpy="0 0 0" xyz="0 0 0"/>
      <geometry>
        <mesh filename="package://rrbot_description/meshes/second_part_of_arm.dae" scale="0.01 0.01 0.01"/>
      </geometry>
    </collision>
    <inertial>
      <origin rpy="0 0 0" xyz="0 0 0"/>
      <mass value="2.231"/>
      <inertia ixx="1" ixy="0.0" ixz="0.0" iyy="1" iyz="0.0" izz="1"/>
    </inertial>
  </link>
  <joint name="joint_second_part" type="revolute">
    <parent link="first_part"/>
    <child link="second_part"/>
    <origin rpy="0 0 3.1415" xyz="-1.5 0 3"/>
    <axis xyz="1 0 0"/>
    <limit effort="100" lower="-6.283" upper="6.283" velocity="100"/>
  </joint>
  <transmission name="tran_joint_second_part">
    <type>transmission_interface/SimpleTransmission</type>
    <joint name="joint_second_part">
      <hardwareInterface>EffortJointInterface</hardwareInterface>
    </joint>
    <actuator name="motor_joint_second_part">
      <hardwareInterface>EffortJointInterface</hardwareInterface>
      <mechanicalReduction>1</mechanicalReduction>
    </actuator>
  </transmission>
  <link name="head">
    <visual>
      <origin rpy="0 0 0" xyz="0 0 0"/>
      <geometry>
        <mesh filename="package://rrbot_description/meshes/head.dae" scale="0.01 0.01 0.01"/>
      </geometry>
      <material name="red"/>
      --&gt;
        
    </visual>
    <collision>
      <origin rpy="0 0 0" xyz="0 0 0"/>
      <geometry>
        <mesh filename="package://rrbot_description/meshes/head.dae" scale="0.01 0.01 0.01"/>
      </geometry>
    </collision>
    <inertial>
      <origin rpy="0 0 0" xyz="0 0 0"/>
      <mass value="2.231"/>
      <inertia ixx="1" ixy="0.0" ixz="0.0" iyy="1" iyz="0.0" izz="1"/>
    </inertial>
  </link>
  <joint name="joint_head" type="revolute">
    <parent link="second_part"/>
    <child link="head"/>
    <origin rpy="3.1415 0.0 3.1415" xyz="0.5 0 -4.2"/>
    <axis xyz="1 0 0"/>
    <limit effort="100" lower="-6.283" upper="6.283" velocity="100"/>
  </joint>
  <transmission name="tran_joint_head">
    <type>transmission_interface/SimpleTransmission</type>
    <joint name="joint_head">
      <hardwareInterface>EffortJointInterface</hardwareInterface>
    </joint>
    <actuator name="motor_joint_head">
      <hardwareInterface>EffortJointInterface</hardwareInterface>
      <mechanicalReduction>1</mechanicalReduction>
    </actuator>
  </transmission>
</robot>

